2022-12-16 01:39:54,164 ERROR: Exception on /index [POST] [in C:\Program Files (x86)\Microsoft Visual Studio\Shared\Python39_64\lib\flask\app.py:1741]
Traceback (most recent call last):
  File "C:\Program Files (x86)\Microsoft Visual Studio\Shared\Python39_64\lib\flask\app.py", line 2525, in wsgi_app
    response = self.full_dispatch_request()
  File "C:\Program Files (x86)\Microsoft Visual Studio\Shared\Python39_64\lib\flask\app.py", line 1822, in full_dispatch_request
    rv = self.handle_user_exception(e)
  File "C:\Program Files (x86)\Microsoft Visual Studio\Shared\Python39_64\lib\flask\app.py", line 1820, in full_dispatch_request
    rv = self.dispatch_request()
  File "C:\Program Files (x86)\Microsoft Visual Studio\Shared\Python39_64\lib\flask\app.py", line 1796, in dispatch_request
    return self.ensure_sync(self.view_functions[rule.endpoint])(**view_args)
  File "D:\Coding\CS50x_Harvard\Final_Project\Blog\env\lib\site-packages\flask_login\utils.py", line 290, in decorated_view
    return current_app.ensure_sync(func)(*args, **kwargs)
  File "D:\Coding\CS50x_Harvard\Final_Project\Blog\app\routes.py", line 34, in index
    db.session.commit()
  File "<string>", line 2, in commit
  File "D:\Coding\CS50x_Harvard\Final_Project\Blog\env\lib\site-packages\sqlalchemy\orm\session.py", line 1451, in commit
    self._transaction.commit(_to_root=self.future)
  File "D:\Coding\CS50x_Harvard\Final_Project\Blog\env\lib\site-packages\sqlalchemy\orm\session.py", line 839, in commit
    self.session.dispatch.after_commit(self.session)
  File "D:\Coding\CS50x_Harvard\Final_Project\Blog\env\lib\site-packages\sqlalchemy\event\attr.py", line 247, in __call__
    fn(*args, **kw)
  File "D:\Coding\CS50x_Harvard\Final_Project\Blog\app\models.py", line 35, in after_commit
    add_to_index(obj.__tablename__, obj)
  File "D:\Coding\CS50x_Harvard\Final_Project\Blog\app\search.py", line 9, in add_to_index
    current_app.elasticsearch.index(index = index,
  File "D:\Coding\CS50x_Harvard\Final_Project\Blog\env\lib\site-packages\elasticsearch\_sync\client\utils.py", line 414, in wrapped
    return api(*args, **kwargs)
TypeError: index() got an unexpected keyword argument 'doc_type'
2022-12-16 01:40:35,663 INFO: Blog startup [in D:\Coding\CS50x_Harvard\Final_Project\Blog\app\__init__.py:54]
2022-12-16 01:41:44,945 INFO: Blog startup [in D:\Coding\CS50x_Harvard\Final_Project\Blog\app\__init__.py:54]
2022-12-16 01:42:31,331 INFO: Blog startup [in D:\Coding\CS50x_Harvard\Final_Project\Blog\app\__init__.py:54]
2022-12-16 01:44:13,661 INFO: Blog startup [in D:\Coding\CS50x_Harvard\Final_Project\Blog\app\__init__.py:54]
2022-12-16 01:45:54,736 INFO: Blog startup [in D:\Coding\CS50x_Harvard\Final_Project\Blog\app\__init__.py:54]
